Workbook

Sheet Uebersicht
A1: RUST & LEAD — Asset-Liste
A2: Alles, was grafisch ins Spiel soll: 3D-Modelle, Texturen, 2D-Icons, VFX und Animationen.
A3: Quellen: godot/scripts/*.gd (Kampf-, Item-, Welt-Daten), docs/MASTER_GDD.md, docs/STORY_BIBLE.md, index.html (Prototyp).
A5: PRIORITAETEN
A6: 1 | B6: Jetzt noetig — ohne diese Assets wirkt das Spiel sichtbar unfertig (Platzhalter-Primitives).
A7: 2 | B7: Bald — rundet Welt und Systeme ab, sobald Prioritaet 1 steht.
A8: 3 | B8: Spaeter / Politur — Story-Setpieces, Nebenstories, Feinschliff.
A10: WORKFLOW (siehe godot/assets/README.md)
A11: • | B11: In Blender entstehen einzelne, wiederverwendbare Module — nicht die fertige Welt.
A12: • | B12: In Godot wird zusammengesetzt: GridMap zum „Malen“ von Strassen/Haeuserzeilen, Path3D fuer Kurven.
A13: • | B13: Datei am Zielpfad ablegen — die AssetRegistry findet sie automatisch, sonst bleibt der Platzhalter.
A14: • | B14: Ausrichtung: +Y oben, Blickrichtung -Z, Pivot am Boden (Fuesse auf Y=0). Groesse egal (Auto-Skalierung).
A16: ZUSAMMENFASSUNG
A17: Asset-Typ | B17: Prio 1 | C17: Prio 2 | D17: Prio 3 | E17: Gesamt | F17: davon vorhanden | G17: offen | I17: Kontrollwert (Stand bei Erstellung)
A18: 3D-Modell | B18: =COUNTIFS('Asset-Liste'!$C$2:$C$174,$A18,'Asset-Liste'!$E$2:$E$174,1) | C18: =COUNTIFS('Asset-Liste'!$C$2:$C$174,$A18,'Asset-Liste'!$E$2:$E$174,2) | D18: =COUNTIFS('Asset-Liste'!$C$2:$C$174,$A18,'Asset-Liste'!$E$2:$E$174,3) | E18: =COUNTIF('Asset-Liste'!$C$2:$C$174,$A18) | F18: =COUNTIFS('Asset-Liste'!$C$2:$C$174,$A18,'Asset-Liste'!$I$2:$I$174,"vorhanden") | G18: =E18-F18 | I18: 115
A19: Textur | B19: =COUNTIFS('Asset-Liste'!$C$2:$C$174,$A19,'Asset-Liste'!$E$2:$E$174,1) | C19: =COUNTIFS('Asset-Liste'!$C$2:$C$174,$A19,'Asset-Liste'!$E$2:$E$174,2) | D19: =COUNTIFS('Asset-Liste'!$C$2:$C$174,$A19,'Asset-Liste'!$E$2:$E$174,3) | E19: =COUNTIF('Asset-Liste'!$C$2:$C$174,$A19) | F19: =COUNTIFS('Asset-Liste'!$C$2:$C$174,$A19,'Asset-Liste'!$I$2:$I$174,"vorhanden") | G19: =E19-F19 | I19: 12
A20: Icon 2D | B20: =COUNTIFS('Asset-Liste'!$C$2:$C$174,$A20,'Asset-Liste'!$E$2:$E$174,1) | C20: =COUNTIFS('Asset-Liste'!$C$2:$C$174,$A20,'Asset-Liste'!$E$2:$E$174,2) | D20: =COUNTIFS('Asset-Liste'!$C$2:$C$174,$A20,'Asset-Liste'!$E$2:$E$174,3) | E20: =COUNTIF('Asset-Liste'!$C$2:$C$174,$A20) | F20: =COUNTIFS('Asset-Liste'!$C$2:$C$174,$A20,'Asset-Liste'!$I$2:$I$174,"vorhanden") | G20: =E20-F20 | I20: 24
A21: Bild 2D | B21: =COUNTIFS('Asset-Liste'!$C$2:$C$174,$A21,'Asset-Liste'!$E$2:$E$174,1) | C21: =COUNTIFS('Asset-Liste'!$C$2:$C$174,$A21,'Asset-Liste'!$E$2:$E$174,2) | D21: =COUNTIFS('Asset-Liste'!$C$2:$C$174,$A21,'Asset-Liste'!$E$2:$E$174,3) | E21: =COUNTIF('Asset-Liste'!$C$2:$C$174,$A21) | F21: =COUNTIFS('Asset-Liste'!$C$2:$C$174,$A21,'Asset-Liste'!$I$2:$I$174,"vorhanden") | G21: =E21-F21 | I21: 1
A22: VFX | B22: =COUNTIFS('Asset-Liste'!$C$2:$C$174,$A22,'Asset-Liste'!$E$2:$E$174,1) | C22: =COUNTIFS('Asset-Liste'!$C$2:$C$174,$A22,'Asset-Liste'!$E$2:$E$174,2) | D22: =COUNTIFS('Asset-Liste'!$C$2:$C$174,$A22,'Asset-Liste'!$E$2:$E$174,3) | E22: =COUNTIF('Asset-Liste'!$C$2:$C$174,$A22) | F22: =COUNTIFS('Asset-Liste'!$C$2:$C$174,$A22,'Asset-Liste'!$I$2:$I$174,"vorhanden") | G22: =E22-F22 | I22: 16
A23: Animation | B23: =COUNTIFS('Asset-Liste'!$C$2:$C$174,$A23,'Asset-Liste'!$E$2:$E$174,1) | C23: =COUNTIFS('Asset-Liste'!$C$2:$C$174,$A23,'Asset-Liste'!$E$2:$E$174,2) | D23: =COUNTIFS('Asset-Liste'!$C$2:$C$174,$A23,'Asset-Liste'!$E$2:$E$174,3) | E23: =COUNTIF('Asset-Liste'!$C$2:$C$174,$A23) | F23: =COUNTIFS('Asset-Liste'!$C$2:$C$174,$A23,'Asset-Liste'!$I$2:$I$174,"vorhanden") | G23: =E23-F23 | I23: 5
A24: SUMME | B24: =SUM(B18:B23) | C24: =SUM(C18:C23) | D24: =SUM(D18:D23) | E24: =SUM(E18:E23) | F24: =SUM(F18:F23) | G24: =SUM(G18:G23) | I24: 173
I26: Hinweis: Spalte E rechnet live mit (COUNTIF). Spalte I ist der
I27: festgehaltene Stand zum Zeitpunkt der Erstellung — weichen beide
I28: ab, wurden Zeilen ergaenzt und die Formelbereiche muessen bis zur
I29: neuen letzten Zeile erweitert werden.

Sheet Asset-Liste
A1: Kategorie | B1: Name | C1: Asset-Typ | D1: Beschreibung / Referenz | E1: Prio | F1: Zielmass | G1: Zielpfad in Godot | H1: Registry-Name | I1: Status
A2: Spieler | B2: Spieler-Chassis (Einheit 13, nach dem Erwachen) | C2: 3D-Modell | D2: Rauchender, einaeugiger Stahlschaedel, Zahnraeder, Schulterventile. Hauptfigur ab Kap. 4 (Story-Bibel Kap. 4.2). | E2: 1 | F2: 1,8 m | G2: assets/models/characters/player.glb | H2: player | I2: offen
A3: Spieler | B3: Spieler-Fleisch-Illusion (vor dem Erwachen) | C3: 3D-Modell | D3: Gleiches Rig, menschliche Huelle. Wird beim Reveal abgeworfen. Kann Material-Variante des Chassis sein. | E3: 2 | F3: 1,8 m | G3: assets/models/characters/player_human.glb | H3: player_human | I3: offen
A4: Spieler | B4: Bolzen (Blechhund, Begleiter) | C4: 3D-Modell | D4: Brass-Koerper, Schlappohr, Antennenschwanz, cyan Auge. Stoesst in Providence Cut dazu. | E4: 2 | F4: 0,7 m | G4: assets/models/characters/bolzen.glb | H4: companion_dog | I4: offen
A5: Spieler | B5: Bolzen — Wrack (zerstoert) | C5: 3D-Modell | D5: Zusammengesunkenes Chassis, als Schrott-Pickup einsammelbar. | E5: 3 | F5: 0,5 m | G5: assets/models/characters/bolzen_wreck.glb | H5: companion_wreck | I5: offen
A6: Gegner | B6: Grenzgaenger (outlaw) | C6: 3D-Modell | D6: BIOLOGISCH — rund + fleischrot (Kampf-Lesbarkeit GDD §8.4). Standard-Nahkaempfer. | E6: 1 | F6: 1,6 m | G6: assets/models/enemies/outlaw.glb | H6: enemy_outlaw | I6: offen
A7: Gegner | B7: Oelfresser-Ratte (fauna) | C7: 3D-Modell | D7: BIOLOGISCH, Schwarm-Gegner, schnell und klein. | E7: 1 | F7: 0,6 m | G7: assets/models/enemies/fauna.glb | H7: enemy_fauna | I7: offen
A8: Gegner | B8: Revolverheld (revolver) | C8: 3D-Modell | D8: BIOLOGISCH, Fernkaempfer — haelt Abstand und feuert. | E8: 1 | F8: 1,6 m | G8: assets/models/enemies/revolver.glb | H8: enemy_revolver | I8: offen
A9: Gegner | B9: Konzern-Konstrukt (konstrukt) | C9: 3D-Modell | D9: MECHANISCH — eckig + stahlblau. Dampf aus Nackenventilen, Gesicht wie zugeschweisste Ofenklappe. | E9: 1 | F9: 1,9 m | G9: assets/models/enemies/konstrukt.glb | H9: enemy_konstrukt | I9: offen
A10: Gegner | B10: Kessel-Klaeffer (klaeffer) | C10: 3D-Modell | D10: MECHANISCH, Schwarm — mechanischer Hund, sehr schnell. | E10: 1 | F10: 0,8 m | G10: assets/models/enemies/klaeffer.glb | H10: enemy_klaeffer | I10: offen
A11: Gegner | B11: Schwerer Ernter / Goliath | C11: 3D-Modell | D11: MECHANISCH, Boss. Frontal panzerimmun (Saeure noetig). Kolben-Telegraph-Angriffe. | E11: 2 | F11: 4,0 m | G11: assets/models/enemies/goliath.glb | H11: enemy_goliath | I11: offen
A12: Gegner | B12: Minen-Titan (Superboss) | C12: 3D-Modell | D12: Dungeon-Titan der Schrott-Minen, Ebene 3. | E12: 3 | F12: 6,0 m | G12: assets/models/enemies/minentitan.glb | H12: enemy_minentitan | I12: offen
A13: Gegner | B13: Schrott-Golem (Superboss) | C13: 3D-Modell | D13: Superboss; garantierter Golem-Faust-Drop. | E13: 3 | F13: 6,0 m | G13: assets/models/enemies/schrottgolem.glb | H13: enemy_schrottgolem | I13: offen
A14: Gegner | B14: Champion-Aura / Unique-Kennzeichnung | C14: VFX | D14: Visuelle Aufwertung fuer benannte Champions (30 % in Kritter-Hallen) — Aura + groessere Silhouette. | E14: 3 | F14: — | G14: assets/vfx/champion_aura | I14: offen
A15: Boss | B15: Kolben-Jack (Zugmeister, Kap. 4) | C15: 3D-Modell | D15: 2 m Vorarbeiter in Konzerngrau, rechter Arm = dampfgetriebene Ramme. | E15: 2 | F15: 2,2 m | G15: assets/models/enemies/kolben_jack.glb | H15: boss_kolbenjack | I15: offen
A16: Boss | B16: Direktor Cornelius Vane — Phase 1 (Wachs) | C16: 3D-Modell | D16: Vaeterliches Wachsgesicht, makelloser Anzug. Endgegner Kap. 12. | E16: 3 | F16: 1,9 m | G16: assets/models/enemies/vane_p1.glb | H16: boss_vane1 | I16: offen
A17: Boss | B17: Direktor Vane — Phase 2 (Direktoren-Chassis) | C17: 3D-Modell | D17: Wachs abgeschmolzen, freigelegtes Stahl-Chassis darunter. | E17: 3 | F17: 2,2 m | G17: assets/models/enemies/vane_p2.glb | H17: boss_vane2 | I17: offen
A18: Boss | B18: Das Eiserne Herz (Phase 3, Maschinenhalle) | C18: 3D-Modell | D18: Hausgrosser Kolbenmotor, wird selbst zum Gegner. Herzschlag-Motiv. | E18: 3 | F18: 25 m | G18: assets/models/enemies/eisernes_herz_boss.glb | H18: boss_herz | I18: offen
A19: NPC | B19: Mamma „Rusty“ Mabel | C19: 3D-Modell | D19: Wirtin des Gatling-Saloons, ~50, Unterarme wie eine Schmiedin. Zentrale Bezugsperson. | E19: 1 | F19: 1,7-1,8 m | G19: assets/models/npcs/ | I19: offen
A20: NPC | B20: Silas „Kupferauge“ Finch | C20: 3D-Modell | D20: Schmied, mechanische Kupferlinse statt Auge, Teilprothesen. | E20: 1 | F20: 1,7-1,8 m | G20: assets/models/npcs/ | I20: offen
A21: NPC | B21: Doktor „Doc“ Aris | C21: 3D-Modell | D21: Feldarzt, hager, Nickelbrille (putzt sie, wenn er luegt). | E21: 1 | F21: 1,7-1,8 m | G21: assets/models/npcs/ | I21: offen
A22: NPC | B22: Pip | C22: 3D-Modell | D22: Waisenkind, 9, Zahnluecke, Schrottsammlerin. Haelt den Helden fuer ihren Schutzengel. | E22: 2 | F22: 1,7-1,8 m | G22: assets/models/npcs/ | I22: offen
A23: NPC | B23: Gideon Cross | C23: 3D-Modell | D23: Rebellenfuehrer, Narbe vom Kinn uebers Ohr. Kanonische Fraktion. | E23: 2 | F23: 1,7-1,8 m | G23: assets/models/npcs/ | I23: offen
A24: NPC | B24: Aufseher Quentin | C24: 3D-Modell | D24: Eiserne Gilde, Uniform ohne Staubkorn, glatt und kuehl. | E24: 3 | F24: 1,7-1,8 m | G24: assets/models/npcs/ | I24: offen
A25: NPC | B25: „Slick“ Sterling | C25: 3D-Modell | D25: Schmuggler-Hehler, bessere Weste als der ganze Canyon. | E25: 3 | F25: 1,7-1,8 m | G25: assets/models/npcs/ | I25: offen
A26: NPC | B26: Elias Roan | C26: 3D-Modell | D26: Providence Cut, Familien-Bogen (roter Faden). | E26: 2 | F26: 1,7-1,8 m | G26: assets/models/npcs/ | I26: offen
A27: NPC | B27: Tessa „Spulen-Tess“ Marlow | C27: 3D-Modell | D27: Signalmeisterin der Rebellen, redet schnell. | E27: 3 | F27: 1,7-1,8 m | G27: assets/models/npcs/ | I27: offen
A28: NPC | B28: Agata Dorn | C28: 3D-Modell | D28: Haelt den Garten aus Rost an der Smog-Linie. | E28: 3 | F28: 1,7-1,8 m | G28: assets/models/npcs/ | I28: offen
A29: NPC | B29: Elias Thorn (Uhrmacher) | C29: 3D-Modell | D29: Nebenstory B1 „Das Uhrwerk-Herz“, Trauerflor am Zylinder. | E29: 3 | F29: 1,7-1,8 m | G29: assets/models/npcs/ | I29: offen
A30: NPC | B30: Oliver (Kinder-Automat) | C30: 3D-Modell | D30: Thorns Automat, Nebenstory B1. | E30: 3 | F30: 1,7-1,8 m | G30: assets/models/npcs/ | I30: offen
... A81: Gebaeude | B81: Erinnerungspunkt / Memorial | C81: 3D-Modell | D81: Interaktionspunkt Providence Cut. | E81: 3 | F81: modular | G81: assets/models/buildings/ | I81: offen
A82: Umgebung | B82: Kaktus (Wueste) | C82: 3D-Modell | D82: Leit-Flora Sektor 1. | E82: 1 | F82: 1-3 m | G82: assets/models/environment/ | H82: flora_cactus | I82: offen
A83: Umgebung | B83: Baum (Oase / Rostwald) | C83: 3D-Modell | D83: Leit-Flora Gruene Senke + Rostwald. | E83: 2 | F83: 4-7 m | G83: assets/models/environment/ | H83: flora_tree | I83: offen
A84: Umgebung | B84: Wasserflaeche (Oase) | C84: 3D-Modell | D84: Gruene Senke. | E84: 3 | F84: — | G84: assets/models/environment/ | H84: flora_water | I84: offen
A85: Umgebung | B85: Salzkruste (Salzpfanne) | C85: 3D-Modell | D85: Boden-Dekor Salzpfanne. | E85: 3 | F85: flach | G85: assets/models/environment/ | H85: flora_salt | I85: offen
A86: Umgebung | B86: Toter Baum (Smog-Oedland) | C86: 3D-Modell | D86: Leit-Flora Sektor 3. | E86: 2 | F86: 4-6 m | G86: assets/models/environment/ | H86: flora_deadtree | I86: offen
A87: Umgebung | B87: Fels klein | C87: 3D-Modell | D87: Vorhanden (CC0 sand_rocks_small_01). | E87: 1 | F87: 0,5 m | G87: assets/models/environment/ | H87: rock_small | I87: vorhanden
A88: Umgebung | B88: Felsbrocken | C88: 3D-Modell | D88: Vorhanden (CC0 namaqualand_boulder_03). | E88: 1 | F88: 1,5 m | G88: assets/models/environment/ | H88: rock_boulder | I88: vorhanden
A89: Umgebung | B89: Klippe | C89: 3D-Modell | D89: Vorhanden (CC0 namaqualand_cliff_02). | E89: 1 | F89: 7 m | G89: assets/models/environment/ | H89: cliff | I89: vorhanden
A90: Umgebung | B90: Kraterrand-Felswand (Modul) | C90: 3D-Modell | D90: Aussengrenze der Welt, 350 m hoch, kachelbar. | E90: 2 | F90: modular | G90: assets/models/environment/ | H90: crater_rim | I90: offen
...
